Traceback (most recent call last):
  File "huirendai.py", line 97, in <module>
    sign(username_array[i], password_array[i])
  File "huirendai.py", line 50, in sign
    login_response = opener.open(login_request).read().decode('utf8').encode('gb18030')
  File "/usr/local/lib/python2.7/urllib2.py", line 410, in open
    response = meth(req, response)
  File "/usr/local/lib/python2.7/urllib2.py", line 523, in http_response
    'http', request, response, code, msg, hdrs)
  File "/usr/local/lib/python2.7/urllib2.py", line 448, in error
    return self._call_chain(*args)
  File "/usr/local/lib/python2.7/urllib2.py", line 382, in _call_chain
    result = func(*args)
  File "/usr/local/lib/python2.7/urllib2.py", line 531, in http_error_default
    raise HTTPError(req.get_full_url(), code, msg, hdrs, fp)
urllib2.HTTPError: HTTP Error 521: 
Traceback (most recent call last):
  File "huirendai.py", line 97, in <module>
    sign(username_array[i], password_array[i])
  File "huirendai.py", line 50, in sign
    login_response = opener.open(login_request).read().decode('utf8').encode('gb18030')
  File "/usr/local/lib/python2.7/urllib2.py", line 410, in open
    response = meth(req, response)
  File "/usr/local/lib/python2.7/urllib2.py", line 523, in http_response
    'http', request, response, code, msg, hdrs)
  File "/usr/local/lib/python2.7/urllib2.py", line 448, in error
    return self._call_chain(*args)
  File "/usr/local/lib/python2.7/urllib2.py", line 382, in _call_chain
    result = func(*args)
  File "/usr/local/lib/python2.7/urllib2.py", line 531, in http_error_default
    raise HTTPError(req.get_full_url(), code, msg, hdrs, fp)
urllib2.HTTPError: HTTP Error 521: 
Traceback (most recent call last):
  File "huirendai.py", line 97, in <module>
    sign(username_array[i], password_array[i])
  File "huirendai.py", line 50, in sign
    login_response = opener.open(login_request).read().decode('utf8').encode('gb18030')
  File "/usr/local/lib/python2.7/urllib2.py", line 410, in open
    response = meth(req, response)
  File "/usr/local/lib/python2.7/urllib2.py", line 523, in http_response
    'http', request, response, code, msg, hdrs)
  File "/usr/local/lib/python2.7/urllib2.py", line 448, in error
    return self._call_chain(*args)
  File "/usr/local/lib/python2.7/urllib2.py", line 382, in _call_chain
    result = func(*args)
  File "/usr/local/lib/python2.7/urllib2.py", line 531, in http_error_default
    raise HTTPError(req.get_full_url(), code, msg, hdrs, fp)
urllib2.HTTPError: HTTP Error 521: 
Traceback (most recent call last):
  File "huirendai.py", line 97, in <module>
    sign(username_array[i], password_array[i])
  File "huirendai.py", line 50, in sign
    login_response = opener.open(login_request).read().decode('utf8').encode('gb18030')
  File "/usr/local/lib/python2.7/urllib2.py", line 410, in open
    response = meth(req, response)
  File "/usr/local/lib/python2.7/urllib2.py", line 523, in http_response
    'http', request, response, code, msg, hdrs)
  File "/usr/local/lib/python2.7/urllib2.py", line 448, in error
    return self._call_chain(*args)
  File "/usr/local/lib/python2.7/urllib2.py", line 382, in _call_chain
    result = func(*args)
  File "/usr/local/lib/python2.7/urllib2.py", line 531, in http_error_default
    raise HTTPError(req.get_full_url(), code, msg, hdrs, fp)
urllib2.HTTPError: HTTP Error 521: 
Traceback (most recent call last):
  File "huirendai.py", line 97, in <module>
    sign(username_array[i], password_array[i])
  File "huirendai.py", line 50, in sign
    login_response = opener.open(login_request).read().decode('utf8').encode('gb18030')
  File "/usr/local/lib/python2.7/urllib2.py", line 410, in open
    response = meth(req, response)
  File "/usr/local/lib/python2.7/urllib2.py", line 523, in http_response
    'http', request, response, code, msg, hdrs)
  File "/usr/local/lib/python2.7/urllib2.py", line 448, in error
    return self._call_chain(*args)
  File "/usr/local/lib/python2.7/urllib2.py", line 382, in _call_chain
    result = func(*args)
  File "/usr/local/lib/python2.7/urllib2.py", line 531, in http_error_default
    raise HTTPError(req.get_full_url(), code, msg, hdrs, fp)
urllib2.HTTPError: HTTP Error 521: 
Traceback (most recent call last):
  File "huirendai.py", line 97, in <module>
    sign(username_array[i], password_array[i])
  File "huirendai.py", line 50, in sign
    login_response = opener.open(login_request).read().decode('utf8').encode('gb18030')
  File "/usr/local/lib/python2.7/urllib2.py", line 410, in open
    response = meth(req, response)
  File "/usr/local/lib/python2.7/urllib2.py", line 523, in http_response
    'http', request, response, code, msg, hdrs)
  File "/usr/local/lib/python2.7/urllib2.py", line 448, in error
    return self._call_chain(*args)
  File "/usr/local/lib/python2.7/urllib2.py", line 382, in _call_chain
    result = func(*args)
  File "/usr/local/lib/python2.7/urllib2.py", line 531, in http_error_default
    raise HTTPError(req.get_full_url(), code, msg, hdrs, fp)
urllib2.HTTPError: HTTP Error 521: 
Traceback (most recent call last):
  File "huirendai.py", line 97, in <module>
    sign(username_array[i], password_array[i])
  File "huirendai.py", line 50, in sign
    login_response = opener.open(login_request).read().decode('utf8').encode('gb18030')
  File "/usr/local/lib/python2.7/urllib2.py", line 410, in open
    response = meth(req, response)
  File "/usr/local/lib/python2.7/urllib2.py", line 523, in http_response
    'http', request, response, code, msg, hdrs)
  File "/usr/local/lib/python2.7/urllib2.py", line 448, in error
    return self._call_chain(*args)
  File "/usr/local/lib/python2.7/urllib2.py", line 382, in _call_chain
    result = func(*args)
  File "/usr/local/lib/python2.7/urllib2.py", line 531, in http_error_default
    raise HTTPError(req.get_full_url(), code, msg, hdrs, fp)
urllib2.HTTPError: HTTP Error 521: 
Traceback (most recent call last):
  File "huirendai.py", line 97, in <module>
    sign(username_array[i], password_array[i])
  File "huirendai.py", line 50, in sign
    login_response = opener.open(login_request).read().decode('utf8').encode('gb18030')
  File "/usr/local/lib/python2.7/urllib2.py", line 410, in open
    response = meth(req, response)
  File "/usr/local/lib/python2.7/urllib2.py", line 523, in http_response
    'http', request, response, code, msg, hdrs)
  File "/usr/local/lib/python2.7/urllib2.py", line 448, in error
    return self._call_chain(*args)
  File "/usr/local/lib/python2.7/urllib2.py", line 382, in _call_chain
    result = func(*args)
  File "/usr/local/lib/python2.7/urllib2.py", line 531, in http_error_default
    raise HTTPError(req.get_full_url(), code, msg, hdrs, fp)
urllib2.HTTPError: HTTP Error 521: 
Traceback (most recent call last):
  File "huirendai.py", line 97, in <module>
    sign(username_array[i], password_array[i])
  File "huirendai.py", line 50, in sign
    login_response = opener.open(login_request).read().decode('utf8').encode('gb18030')
  File "/usr/local/lib/python2.7/urllib2.py", line 410, in open
    response = meth(req, response)
  File "/usr/local/lib/python2.7/urllib2.py", line 523, in http_response
    'http', request, response, code, msg, hdrs)
  File "/usr/local/lib/python2.7/urllib2.py", line 448, in error
    return self._call_chain(*args)
  File "/usr/local/lib/python2.7/urllib2.py", line 382, in _call_chain
    result = func(*args)
  File "/usr/local/lib/python2.7/urllib2.py", line 531, in http_error_default
    raise HTTPError(req.get_full_url(), code, msg, hdrs, fp)
urllib2.HTTPError: HTTP Error 521: 
Traceback (most recent call last):
  File "huirendai.py", line 97, in <module>
    sign(username_array[i], password_array[i])
  File "huirendai.py", line 50, in sign
    login_response = opener.open(login_request).read().decode('utf8').encode('gb18030')
  File "/usr/local/lib/python2.7/urllib2.py", line 410, in open
    response = meth(req, response)
  File "/usr/local/lib/python2.7/urllib2.py", line 523, in http_response
    'http', request, response, code, msg, hdrs)
  File "/usr/local/lib/python2.7/urllib2.py", line 448, in error
    return self._call_chain(*args)
  File "/usr/local/lib/python2.7/urllib2.py", line 382, in _call_chain
    result = func(*args)
  File "/usr/local/lib/python2.7/urllib2.py", line 531, in http_error_default
    raise HTTPError(req.get_full_url(), code, msg, hdrs, fp)
urllib2.HTTPError: HTTP Error 521: 
Traceback (most recent call last):
  File "huirendai.py", line 97, in <module>
    sign(username_array[i], password_array[i])
  File "huirendai.py", line 50, in sign
    login_response = opener.open(login_request).read().decode('utf8').encode('gb18030')
  File "/usr/local/lib/python2.7/urllib2.py", line 410, in open
    response = meth(req, response)
  File "/usr/local/lib/python2.7/urllib2.py", line 523, in http_response
    'http', request, response, code, msg, hdrs)
  File "/usr/local/lib/python2.7/urllib2.py", line 448, in error
    return self._call_chain(*args)
  File "/usr/local/lib/python2.7/urllib2.py", line 382, in _call_chain
    result = func(*args)
  File "/usr/local/lib/python2.7/urllib2.py", line 531, in http_error_default
    raise HTTPError(req.get_full_url(), code, msg, hdrs, fp)
urllib2.HTTPError: HTTP Error 521: 
Traceback (most recent call last):
  File "huirendai.py", line 97, in <module>
    sign(username_array[i], password_array[i])
  File "huirendai.py", line 50, in sign
    login_response = opener.open(login_request).read().decode('utf8').encode('gb18030')
  File "/usr/local/lib/python2.7/urllib2.py", line 410, in open
    response = meth(req, response)
  File "/usr/local/lib/python2.7/urllib2.py", line 523, in http_response
    'http', request, response, code, msg, hdrs)
  File "/usr/local/lib/python2.7/urllib2.py", line 448, in error
    return self._call_chain(*args)
  File "/usr/local/lib/python2.7/urllib2.py", line 382, in _call_chain
    result = func(*args)
  File "/usr/local/lib/python2.7/urllib2.py", line 531, in http_error_default
    raise HTTPError(req.get_full_url(), code, msg, hdrs, fp)
urllib2.HTTPError: HTTP Error 521: 
Traceback (most recent call last):
  File "huirendai.py", line 97, in <module>
    sign(username_array[i], password_array[i])
  File "huirendai.py", line 50, in sign
    login_response = opener.open(login_request).read().decode('utf8').encode('gb18030')
  File "/usr/local/lib/python2.7/urllib2.py", line 410, in open
    response = meth(req, response)
  File "/usr/local/lib/python2.7/urllib2.py", line 523, in http_response
    'http', request, response, code, msg, hdrs)
  File "/usr/local/lib/python2.7/urllib2.py", line 448, in error
    return self._call_chain(*args)
  File "/usr/local/lib/python2.7/urllib2.py", line 382, in _call_chain
    result = func(*args)
  File "/usr/local/lib/python2.7/urllib2.py", line 531, in http_error_default
    raise HTTPError(req.get_full_url(), code, msg, hdrs, fp)
urllib2.HTTPError: HTTP Error 521: 
Traceback (most recent call last):
  File "huirendai.py", line 97, in <module>
    sign(username_array[i], password_array[i])
  File "huirendai.py", line 50, in sign
    login_response = opener.open(login_request).read().decode('utf8').encode('gb18030')
  File "/usr/local/lib/python2.7/urllib2.py", line 410, in open
    response = meth(req, response)
  File "/usr/local/lib/python2.7/urllib2.py", line 523, in http_response
    'http', request, response, code, msg, hdrs)
  File "/usr/local/lib/python2.7/urllib2.py", line 448, in error
    return self._call_chain(*args)
  File "/usr/local/lib/python2.7/urllib2.py", line 382, in _call_chain
    result = func(*args)
  File "/usr/local/lib/python2.7/urllib2.py", line 531, in http_error_default
    raise HTTPError(req.get_full_url(), code, msg, hdrs, fp)
urllib2.HTTPError: HTTP Error 521: 
Traceback (most recent call last):
  File "huirendai.py", line 97, in <module>
    sign(username_array[i], password_array[i])
  File "huirendai.py", line 50, in sign
    login_response = opener.open(login_request).read().decode('utf8').encode('gb18030')
  File "/usr/local/lib/python2.7/urllib2.py", line 410, in open
    response = meth(req, response)
  File "/usr/local/lib/python2.7/urllib2.py", line 523, in http_response
    'http', request, response, code, msg, hdrs)
  File "/usr/local/lib/python2.7/urllib2.py", line 448, in error
    return self._call_chain(*args)
  File "/usr/local/lib/python2.7/urllib2.py", line 382, in _call_chain
    result = func(*args)
  File "/usr/local/lib/python2.7/urllib2.py", line 531, in http_error_default
    raise HTTPError(req.get_full_url(), code, msg, hdrs, fp)
urllib2.HTTPError: HTTP Error 521: 
Traceback (most recent call last):
  File "huirendai.py", line 97, in <module>
    sign(username_array[i], password_array[i])
  File "huirendai.py", line 50, in sign
    login_response = opener.open(login_request).read().decode('utf8').encode('gb18030')
  File "/usr/local/lib/python2.7/urllib2.py", line 410, in open
    response = meth(req, response)
  File "/usr/local/lib/python2.7/urllib2.py", line 523, in http_response
    'http', request, response, code, msg, hdrs)
  File "/usr/local/lib/python2.7/urllib2.py", line 448, in error
    return self._call_chain(*args)
  File "/usr/local/lib/python2.7/urllib2.py", line 382, in _call_chain
    result = func(*args)
  File "/usr/local/lib/python2.7/urllib2.py", line 531, in http_error_default
    raise HTTPError(req.get_full_url(), code, msg, hdrs, fp)
urllib2.HTTPError: HTTP Error 521: 
Traceback (most recent call last):
  File "huirendai.py", line 97, in <module>
    sign(username_array[i], password_array[i])
  File "huirendai.py", line 50, in sign
    login_response = opener.open(login_request).read().decode('utf8').encode('gb18030')
  File "/usr/local/lib/python2.7/urllib2.py", line 410, in open
    response = meth(req, response)
  File "/usr/local/lib/python2.7/urllib2.py", line 523, in http_response
    'http', request, response, code, msg, hdrs)
  File "/usr/local/lib/python2.7/urllib2.py", line 448, in error
    return self._call_chain(*args)
  File "/usr/local/lib/python2.7/urllib2.py", line 382, in _call_chain
    result = func(*args)
  File "/usr/local/lib/python2.7/urllib2.py", line 531, in http_error_default
    raise HTTPError(req.get_full_url(), code, msg, hdrs, fp)
urllib2.HTTPError: HTTP Error 521: 
Traceback (most recent call last):
  File "huirendai.py", line 97, in <module>
    sign(username_array[i], password_array[i])
  File "huirendai.py", line 50, in sign
    login_response = opener.open(login_request).read().decode('utf8').encode('gb18030')
  File "/usr/local/lib/python2.7/urllib2.py", line 410, in open
    response = meth(req, response)
  File "/usr/local/lib/python2.7/urllib2.py", line 523, in http_response
    'http', request, response, code, msg, hdrs)
  File "/usr/local/lib/python2.7/urllib2.py", line 448, in error
    return self._call_chain(*args)
  File "/usr/local/lib/python2.7/urllib2.py", line 382, in _call_chain
    result = func(*args)
  File "/usr/local/lib/python2.7/urllib2.py", line 531, in http_error_default
    raise HTTPError(req.get_full_url(), code, msg, hdrs, fp)
urllib2.HTTPError: HTTP Error 521: 
