Traceback (most recent call last):
  File "9888.py", line 114, in ?
    sign(username_array[i], password_array[i])
  File "9888.py", line 62, in sign
    login_response = opener.open(login_request).read()
  File "/usr/lib64/python2.4/urllib2.py", line 364, in open
    response = meth(req, response)
  File "/usr/lib64/python2.4/urllib2.py", line 471, in http_response
    response = self.parent.error(
  File "/usr/lib64/python2.4/urllib2.py", line 396, in error
    result = self._call_chain(*args)
  File "/usr/lib64/python2.4/urllib2.py", line 337, in _call_chain
    result = func(*args)
  File "/usr/lib64/python2.4/urllib2.py", line 565, in http_error_302
    return self.parent.open(new)
  File "/usr/lib64/python2.4/urllib2.py", line 358, in open
    response = self._open(req, data)
  File "/usr/lib64/python2.4/urllib2.py", line 376, in _open
    '_open', req)
  File "/usr/lib64/python2.4/urllib2.py", line 337, in _call_chain
    result = func(*args)
  File "/usr/lib64/python2.4/urllib2.py", line 1118, in http_open
    return self.do_open(httplib.HTTPConnection, req)
  File "/usr/lib64/python2.4/urllib2.py", line 1092, in do_open
    raise URLError(err)
urllib2.URLError: <urlopen error (-2, 'Name or service not known')>
Traceback (most recent call last):
  File "9888.py", line 113, in <module>
    sign(username_array[i], password_array[i])
  File "9888.py", line 63, in sign
    login_response = opener.open(login_request).read()
  File "/usr/local/lib/python2.7/urllib2.py", line 410, in open
    response = meth(req, response)
  File "/usr/local/lib/python2.7/urllib2.py", line 523, in http_response
    'http', request, response, code, msg, hdrs)
  File "/usr/local/lib/python2.7/urllib2.py", line 442, in error
    result = self._call_chain(*args)
  File "/usr/local/lib/python2.7/urllib2.py", line 382, in _call_chain
    result = func(*args)
  File "/usr/local/lib/python2.7/urllib2.py", line 629, in http_error_302
    return self.parent.open(new, timeout=req.timeout)
  File "/usr/local/lib/python2.7/urllib2.py", line 404, in open
    response = self._open(req, data)
  File "/usr/local/lib/python2.7/urllib2.py", line 422, in _open
    '_open', req)
  File "/usr/local/lib/python2.7/urllib2.py", line 382, in _call_chain
    result = func(*args)
  File "/usr/local/lib/python2.7/urllib2.py", line 1214, in http_open
    return self.do_open(httplib.HTTPConnection, req)
  File "/usr/local/lib/python2.7/urllib2.py", line 1187, in do_open
    r = h.getresponse(buffering=True)
  File "/usr/local/lib/python2.7/httplib.py", line 1067, in getresponse
    response.begin()
  File "/usr/local/lib/python2.7/httplib.py", line 409, in begin
    version, status, reason = self._read_status()
  File "/usr/local/lib/python2.7/httplib.py", line 373, in _read_status
    raise BadStatusLine(line)
httplib.BadStatusLine: ''
Traceback (most recent call last):
  File "9888.py", line 113, in <module>
    sign(username_array[i], password_array[i])
  File "9888.py", line 63, in sign
    login_response = opener.open(login_request).read()
  File "/usr/local/lib/python2.7/urllib2.py", line 404, in open
    response = self._open(req, data)
  File "/usr/local/lib/python2.7/urllib2.py", line 422, in _open
    '_open', req)
  File "/usr/local/lib/python2.7/urllib2.py", line 382, in _call_chain
    result = func(*args)
  File "/usr/local/lib/python2.7/urllib2.py", line 1222, in https_open
    return self.do_open(httplib.HTTPSConnection, req)
  File "/usr/local/lib/python2.7/urllib2.py", line 1187, in do_open
    r = h.getresponse(buffering=True)
  File "/usr/local/lib/python2.7/httplib.py", line 1067, in getresponse
    response.begin()
  File "/usr/local/lib/python2.7/httplib.py", line 409, in begin
    version, status, reason = self._read_status()
  File "/usr/local/lib/python2.7/httplib.py", line 365, in _read_status
    line = self.fp.readline(_MAXLINE + 1)
  File "/usr/local/lib/python2.7/socket.py", line 476, in readline
    data = self._sock.recv(self._rbufsize)
  File "/usr/local/lib/python2.7/ssl.py", line 246, in recv
    return self.read(buflen)
  File "/usr/local/lib/python2.7/ssl.py", line 165, in read
    return self._sslobj.read(len)
KeyboardInterrupt
Traceback (most recent call last):
  File "9888.py", line 113, in ?
    sign(username_array[i], password_array[i])
  File "9888.py", line 63, in sign
    login_response = opener.open(login_request).read()
  File "/usr/lib64/python2.4/urllib2.py", line 364, in open
    response = meth(req, response)
  File "/usr/lib64/python2.4/urllib2.py", line 471, in http_response
    response = self.parent.error(
  File "/usr/lib64/python2.4/urllib2.py", line 396, in error
    result = self._call_chain(*args)
  File "/usr/lib64/python2.4/urllib2.py", line 337, in _call_chain
    result = func(*args)
  File "/usr/lib64/python2.4/urllib2.py", line 565, in http_error_302
    return self.parent.open(new)
  File "/usr/lib64/python2.4/urllib2.py", line 358, in open
    response = self._open(req, data)
  File "/usr/lib64/python2.4/urllib2.py", line 376, in _open
    '_open', req)
  File "/usr/lib64/python2.4/urllib2.py", line 337, in _call_chain
    result = func(*args)
  File "/usr/lib64/python2.4/urllib2.py", line 1118, in http_open
    return self.do_open(httplib.HTTPConnection, req)
  File "/usr/lib64/python2.4/urllib2.py", line 1092, in do_open
    raise URLError(err)
urllib2.URLError: <urlopen error (-2, 'Name or service not known')>
Traceback (most recent call last):
  File "9888.py", line 113, in ?
    sign(username_array[i], password_array[i])
  File "9888.py", line 63, in sign
    login_response = opener.open(login_request).read()
  File "/usr/lib64/python2.4/urllib2.py", line 364, in open
    response = meth(req, response)
  File "/usr/lib64/python2.4/urllib2.py", line 471, in http_response
    response = self.parent.error(
  File "/usr/lib64/python2.4/urllib2.py", line 396, in error
    result = self._call_chain(*args)
  File "/usr/lib64/python2.4/urllib2.py", line 337, in _call_chain
    result = func(*args)
  File "/usr/lib64/python2.4/urllib2.py", line 565, in http_error_302
    return self.parent.open(new)
  File "/usr/lib64/python2.4/urllib2.py", line 358, in open
    response = self._open(req, data)
  File "/usr/lib64/python2.4/urllib2.py", line 376, in _open
    '_open', req)
  File "/usr/lib64/python2.4/urllib2.py", line 337, in _call_chain
    result = func(*args)
  File "/usr/lib64/python2.4/urllib2.py", line 1118, in http_open
    return self.do_open(httplib.HTTPConnection, req)
  File "/usr/lib64/python2.4/urllib2.py", line 1092, in do_open
    raise URLError(err)
urllib2.URLError: <urlopen error (-2, 'Name or service not known')>
Traceback (most recent call last):
  File "9888.py", line 113, in ?
    sign(username_array[i], password_array[i])
  File "9888.py", line 63, in sign
    login_response = opener.open(login_request).read()
  File "/usr/lib64/python2.4/urllib2.py", line 364, in open
    response = meth(req, response)
  File "/usr/lib64/python2.4/urllib2.py", line 471, in http_response
    response = self.parent.error(
  File "/usr/lib64/python2.4/urllib2.py", line 396, in error
    result = self._call_chain(*args)
  File "/usr/lib64/python2.4/urllib2.py", line 337, in _call_chain
    result = func(*args)
  File "/usr/lib64/python2.4/urllib2.py", line 565, in http_error_302
    return self.parent.open(new)
  File "/usr/lib64/python2.4/urllib2.py", line 358, in open
    response = self._open(req, data)
  File "/usr/lib64/python2.4/urllib2.py", line 376, in _open
    '_open', req)
  File "/usr/lib64/python2.4/urllib2.py", line 337, in _call_chain
    result = func(*args)
  File "/usr/lib64/python2.4/urllib2.py", line 1118, in http_open
    return self.do_open(httplib.HTTPConnection, req)
  File "/usr/lib64/python2.4/urllib2.py", line 1092, in do_open
    raise URLError(err)
urllib2.URLError: <urlopen error (-2, 'Name or service not known')>
